Warning: Permanently added '[localhost]:3022' (ED25519) to the list of known hosts.
#0 building with "default" instance using docker driver

#1 [internal] load build definition from Dockerfile
#1 transferring dockerfile: 254B done
#1 DONE 0.1s

#2 [internal] load metadata for docker.io/library/python:3.8
#2 ...

#3 [auth] library/python:pull token for registry-1.docker.io
#3 DONE 0.0s

#2 [internal] load metadata for docker.io/library/python:3.8
#2 DONE 1.5s

#4 [internal] load .dockerignore
#4 transferring context: 2B done
#4 DONE 0.1s

#5 [1/5] FROM docker.io/library/python:3.8@sha256:01a4da15f16395a2d17dd9b673ccedcd6a6dbb4e130c8056d0d804dedac11c81
#5 CACHED

#6 [2/5] RUN apt-get -y update && n    apt-get -y install git
#6 0.416 Get:1 http://deb.debian.org/debian bookworm InRelease [151 kB]
#6 0.463 Get:2 http://deb.debian.org/debian bookworm-updates InRelease [55.4 kB]
#6 0.497 Get:3 http://deb.debian.org/debian-security bookworm-security InRelease [48.0 kB]
#6 0.528 Get:4 http://deb.debian.org/debian bookworm/main amd64 Packages [8786 kB]
#6 3.399 Get:5 http://deb.debian.org/debian bookworm-updates/main amd64 Packages [13.8 kB]
#6 3.423 Get:6 http://deb.debian.org/debian-security bookworm-security/main amd64 Packages [156 kB]
#6 4.117 Fetched 9210 kB in 4s (2446 kB/s)
#6 4.117 Reading package lists...
#6 4.481 /bin/sh: 1: n: not found
#6 ERROR: process "/bin/sh -c apt-get -y update && \\n    apt-get -y install git" did not complete successfully: exit code: 127
------
 > [2/5] RUN apt-get -y update && n    apt-get -y install git:
0.416 Get:1 http://deb.debian.org/debian bookworm InRelease [151 kB]
0.463 Get:2 http://deb.debian.org/debian bookworm-updates InRelease [55.4 kB]
0.497 Get:3 http://deb.debian.org/debian-security bookworm-security InRelease [48.0 kB]
0.528 Get:4 http://deb.debian.org/debian bookworm/main amd64 Packages [8786 kB]
3.399 Get:5 http://deb.debian.org/debian bookworm-updates/main amd64 Packages [13.8 kB]
3.423 Get:6 http://deb.debian.org/debian-security bookworm-security/main amd64 Packages [156 kB]

4.481 /bin/sh: 1: n: not found
------
Dockerfile:3
--------------------
   1 |     FROM python:3.8
   2 |     
   3 | >>> RUN apt-get -y update && \n    apt-get -y install git
   4 |     
   5 |     RUN git clone https://github.com/tqdm/tqdm.git && \n    pip install -e tqdm
--------------------
ERROR: failed to solve: process "/bin/sh -c apt-get -y update && \\n    apt-get -y install git" did not complete successfully: exit code: 127
machine already started
TEMP DIR: /tmp/tmp.FojkZqzLiH


Warning: Permanently added '[localhost]:3022' (ED25519) to the list of known hosts.
#0 building with "default" instance using docker driver

#1 [internal] load build definition from Dockerfile
#1 transferring dockerfile: 235B done
#1 DONE 0.1s

#2 [internal] load metadata for docker.io/library/python:3.8
#2 DONE 0.8s

#3 [internal] load .dockerignore
#3 transferring context: 2B done
#3 DONE 0.1s

#4 [1/5] FROM docker.io/library/python:3.8@sha256:01a4da15f16395a2d17dd9b673ccedcd6a6dbb4e130c8056d0d804dedac11c81
#4 CACHED

#5 [2/5] RUN apt-get update && apt-get install -y git
#5 0.653 Get:1 http://deb.debian.org/debian bookworm InRelease [151 kB]
#5 0.724 Get:2 http://deb.debian.org/debian bookworm-updates InRelease [55.4 kB]
#5 0.741 Get:3 http://deb.debian.org/debian-security bookworm-security InRelease [48.0 kB]
#5 0.792 Get:4 http://deb.debian.org/debian bookworm/main amd64 Packages [8786 kB]
#5 4.116 Get:5 http://deb.debian.org/debian bookworm-updates/main amd64 Packages [13.8 kB]
#5 4.125 Get:6 http://deb.debian.org/debian-security bookworm-security/main amd64 Packages [156 kB]
#5 4.850 Fetched 9210 kB in 5s (2033 kB/s)
#5 4.850 Reading package lists...
#5 5.240 Reading package lists...
#5 5.648 Building dependency tree...
#5 5.745 Reading state information...
#5 5.861 git is already the newest version (1:2.39.2-1.1).
#5 5.861 0 upgraded, 0 newly installed, 0 to remove and 0 not upgraded.
#5 DONE 6.0s

#6 [3/5] WORKDIR /app
#6 DONE 0.2s

#7 [4/5] RUN git clone https://github.com/tqdm/tqdm.git .
#7 0.280 Cloning into '.'...
#7 DONE 3.4s

#8 [5/5] RUN pip install -r requirements.txt
#8 1.290 ERROR: Could not open requirements file: [Errno 2] No such file or directory: 'requirements.txt'
#8 1.414 
#8 1.414 [notice] A new release of pip is available: 23.0.1 -> 24.0
#8 1.414 [notice] To update, run: pip install --upgrade pip
#8 ERROR: process "/bin/sh -c pip install -r requirements.txt" did not complete successfully: exit code: 1
------
 > [5/5] RUN pip install -r requirements.txt:
1.290 ERROR: Could not open requirements file: [Errno 2] No such file or directory: 'requirements.txt'
1.414 
1.414 [notice] A new release of pip is available: 23.0.1 -> 24.0
1.414 [notice] To update, run: pip install --upgrade pip
------
Dockerfile:9
--------------------
   7 |     RUN git clone https://github.com/tqdm/tqdm.git .
   8 |     
   9 | >>> RUN pip install -r requirements.txt
  10 |     
  11 |     CMD ["python", "-m", "unittest"]
--------------------
ERROR: failed to solve: process "/bin/sh -c pip install -r requirements.txt" did not complete successfully: exit code: 1
removing docker image...
clearing temp directory
machine already started
TEMP DIR: /tmp/tmp.bwPBxYEnGX


Warning: Permanently added '[localhost]:3022' (ED25519) to the list of known hosts.
#0 building with "default" instance using docker driver

#1 [internal] load build definition from Dockerfile
#1 transferring dockerfile: 366B done
#1 DONE 0.1s

#2 [internal] load metadata for docker.io/library/python:3.8
#2 DONE 0.8s

#3 [internal] load .dockerignore
#3 transferring context: 2B done
#3 DONE 0.0s

#4 [1/5] FROM docker.io/library/python:3.8@sha256:01a4da15f16395a2d17dd9b673ccedcd6a6dbb4e130c8056d0d804dedac11c81
#4 DONE 0.0s

#5 [2/5] WORKDIR /app
#5 CACHED

#6 [3/5] RUN git clone https://github.com/tqdm/tqdm.git .
#6 0.304 Cloning into '.'...
#6 DONE 4.3s

#7 [4/5] RUN pip install .
#7 1.329 Processing /app
#7 1.333   Installing build dependencies: started
#7 4.595   Installing build dependencies: finished with status 'done'
#7 4.597   Getting requirements to build wheel: started
#7 4.906   Getting requirements to build wheel: finished with status 'done'
#7 4.909   Preparing metadata (pyproject.toml): started
#7 5.180   Preparing metadata (pyproject.toml): finished with status 'done'
#7 5.193 Building wheels for collected packages: tqdm
#7 5.194   Building wheel for tqdm (pyproject.toml): started
#7 5.507   Building wheel for tqdm (pyproject.toml): finished with status 'done'
#7 5.508   Created wheel for tqdm: filename=tqdm-4.66.4-py3-none-any.whl size=78283 sha256=b11f20287726c134dfa6e4fce31566886177bf5579c276a8fa2ae6236393c5d3
#7 5.509   Stored in directory: /tmp/pip-ephem-wheel-cache-kv3a8ll4/wheels/40/5d/89/f38b7a58cbc6f6bdff423c409ca06a097d4abae527d8c17f06
#7 5.514 Successfully built tqdm
#7 5.540 Installing collected packages: tqdm
#7 5.605 Successfully installed tqdm-4.66.4
#7 5.605 WARNING: Running pip as the 'root' user can result in broken permissions and conflicting behaviour with the system package manager. It is recommended to use a virtual environment instead: https://pip.pypa.io/warnings/venv
#7 5.611 
#7 5.611 [notice] A new release of pip is available: 23.0.1 -> 24.0
#7 5.611 [notice] To update, run: pip install --upgrade pip
#7 DONE 5.7s

#8 [5/5] RUN python -m unittest discover -s tests -p '*_test.py'
#8 0.427 
#8 0.427 ----------------------------------------------------------------------
#8 0.427 Ran 0 tests in 0.000s
#8 0.427 
#8 0.427 OK
#8 DONE 0.5s

#9 exporting to image
#9 exporting layers
#9 exporting layers 0.3s done
#9 writing image sha256:d6264c59c091ec8e0c492e5086cb28774e0a919a31a2cc799a1745ae316214b6
#9 writing image sha256:d6264c59c091ec8e0c492e5086cb28774e0a919a31a2cc799a1745ae316214b6 done
#9 naming to docker.io/library/temp_image done
#9 DONE 0.3s
Docker build completed successfully on virtual machine.
removing docker image...
clearing temp directory
machine already started
TEMP DIR: /tmp/tmp.eST0PzdYLU


Warning: Permanently added '[localhost]:3022' (ED25519) to the list of known hosts.
#0 building with "default" instance using docker driver

#1 [internal] load build definition from Dockerfile
#1 transferring dockerfile: 407B done
#1 DONE 0.1s

#2 [internal] load metadata for docker.io/library/python:3.8
#2 DONE 0.8s

#3 [internal] load .dockerignore
#3 transferring context: 2B done
#3 DONE 0.1s

#4 [1/5] FROM docker.io/library/python:3.8@sha256:01a4da15f16395a2d17dd9b673ccedcd6a6dbb4e130c8056d0d804dedac11c81
#4 DONE 0.0s

#5 [2/5] WORKDIR /app
#5 CACHED

#6 [3/5] RUN git clone https://github.com/tqdm/tqdm.git
#6 0.261 Cloning into 'tqdm'...
#6 DONE 6.9s

#7 [4/5] WORKDIR /app/tqdm
#7 DONE 0.1s

#8 [5/5] RUN python setup.py test
#8 0.325 python: can't open file 'setup.py': [Errno 2] No such file or directory
#8 ERROR: process "/bin/sh -c python setup.py test" did not complete successfully: exit code: 2
------
 > [5/5] RUN python setup.py test:
0.325 python: can't open file 'setup.py': [Errno 2] No such file or directory
------
Dockerfile:14
--------------------
  12 |     
  13 |     # Run the test suite
  14 | >>> RUN python setup.py test
  15 |     
  16 |     # Set the default command for the container
--------------------
ERROR: failed to solve: process "/bin/sh -c python setup.py test" did not complete successfully: exit code: 2
removing docker image...
clearing temp directory
machine already started
TEMP DIR: /tmp/tmp.VYEgzc3jlj


Warning: Permanently added '[localhost]:3022' (ED25519) to the list of known hosts.
#0 building with "default" instance using docker driver

#1 [internal] load build definition from Dockerfile
#1 transferring dockerfile: 336B done
#1 DONE 0.1s

#2 [internal] load metadata for docker.io/library/python:3.8
#2 DONE 0.8s

#3 [internal] load .dockerignore
#3 transferring context: 2B done
#3 DONE 0.1s

#4 [1/5] FROM docker.io/library/python:3.8@sha256:01a4da15f16395a2d17dd9b673ccedcd6a6dbb4e130c8056d0d804dedac11c81
#4 DONE 0.0s

#5 [2/5] WORKDIR /app
#5 CACHED

#6 [3/5] RUN git clone https://github.com/tqdm/tqdm.git .
#6 0.270 Cloning into '.'...
#6 DONE 3.5s

#7 [4/5] RUN pip install .
#7 1.323 Processing /app
#7 1.327   Installing build dependencies: started
#7 3.625   Installing build dependencies: finished with status 'done'
#7 3.626   Getting requirements to build wheel: started
#7 3.921   Getting requirements to build wheel: finished with status 'done'
#7 3.924   Preparing metadata (pyproject.toml): started
#7 4.189   Preparing metadata (pyproject.toml): finished with status 'done'
#7 4.202 Building wheels for collected packages: tqdm
#7 4.203   Building wheel for tqdm (pyproject.toml): started
#7 4.512   Building wheel for tqdm (pyproject.toml): finished with status 'done'
#7 4.513   Created wheel for tqdm: filename=tqdm-4.66.4-py3-none-any.whl size=78283 sha256=6bf8c354081f72c74074364af21a078e3f3ffa49ddca27c60c5d6d7e6db27708
#7 4.513   Stored in directory: /tmp/pip-ephem-wheel-cache-n3qsne1h/wheels/40/5d/89/f38b7a58cbc6f6bdff423c409ca06a097d4abae527d8c17f06
#7 4.518 Successfully built tqdm
#7 4.545 Installing collected packages: tqdm
#7 4.611 Successfully installed tqdm-4.66.4
#7 4.611 WARNING: Running pip as the 'root' user can result in broken permissions and conflicting behaviour with the system package manager. It is recommended to use a virtual environment instead: https://pip.pypa.io/warnings/venv
#7 4.616 
#7 4.616 [notice] A new release of pip is available: 23.0.1 -> 24.0
#7 4.616 [notice] To update, run: pip install --upgrade pip
#7 DONE 4.7s

#8 [5/5] RUN pytest
#8 0.334 /bin/sh: 1: pytest: not found
#8 ERROR: process "/bin/sh -c pytest" did not complete successfully: exit code: 127
------
 > [5/5] RUN pytest:
pytest: not found
------
Dockerfile:14
--------------------
  12 |     
  13 |     # Run the test suite
  14 | >>> RUN pytest
--------------------
ERROR: failed to solve: process "/bin/sh -c pytest" did not complete successfully: exit code: 127
removing docker image...
clearing temp directory
machine already started
TEMP DIR: /tmp/tmp.shnE6NMhdr


Warning: Permanently added '[localhost]:3022' (ED25519) to the list of known hosts.
#0 building with "default" instance using docker driver

#1 [internal] load build definition from Dockerfile
#1 transferring dockerfile: 272B done
#1 DONE 0.1s

#2 [internal] load metadata for docker.io/library/python:3.8
#2 DONE 0.9s

#3 [internal] load .dockerignore
#3 transferring context: 2B done
#3 DONE 0.1s

#4 [1/3] FROM docker.io/library/python:3.8@sha256:01a4da15f16395a2d17dd9b673ccedcd6a6dbb4e130c8056d0d804dedac11c81
#4 DONE 0.0s

#5 [2/3] WORKDIR /app
#5 CACHED

#6 [internal] load build context
#6 transferring context: 272B done
#6 DONE 0.1s

#7 [3/3] COPY . /app
#7 DONE 0.1s

#8 exporting to image
#8 exporting layers 0.1s done
#8 writing image sha256:7672d8036cd6f0452c6587a8c98a66031be895fd598e5bd74993e7f0a7a6a12f done
#8 naming to docker.io/library/temp_image 0.0s done
#8 DONE 0.1s
Docker build completed successfully on virtual machine.
removing docker image...
clearing temp directory
machine already started
TEMP DIR: /tmp/tmp.Ypy64KJoM7


Warning: Permanently added '[localhost]:3022' (ED25519) to the list of known hosts.
#0 building with "default" instance using docker driver

#1 [internal] load build definition from Dockerfile
#1 transferring dockerfile: 408B done
#1 DONE 0.1s

#2 [internal] load metadata for docker.io/library/python:3.8
#2 DONE 0.8s

#3 [internal] load .dockerignore
#3 transferring context: 2B done
#3 DONE 0.1s

#4 [1/5] FROM docker.io/library/python:3.8@sha256:01a4da15f16395a2d17dd9b673ccedcd6a6dbb4e130c8056d0d804dedac11c81
#4 DONE 0.0s

#5 [2/5] WORKDIR /app
#5 CACHED

#6 [3/5] RUN git clone https://github.com/tqdm/tqdm.git
#6 0.259 Cloning into 'tqdm'...
#6 DONE 4.7s

#7 [4/5] WORKDIR /app/tqdm
#7 DONE 0.2s

#8 [5/5] RUN pip install .
#8 2.414 Processing /app/tqdm
#8 2.419   Installing build dependencies: started
#8 6.544   Installing build dependencies: finished with status 'done'
#8 6.562   Getting requirements to build wheel: started
#8 7.225   Getting requirements to build wheel: finished with status 'done'
#8 7.229   Preparing metadata (pyproject.toml): started
#8 7.858   Preparing metadata (pyproject.toml): finished with status 'done'
#8 7.870 Building wheels for collected packages: tqdm
#8 7.891   Building wheel for tqdm (pyproject.toml): started
#8 8.586   Building wheel for tqdm (pyproject.toml): finished with status 'done'
#8 8.587   Created wheel for tqdm: filename=tqdm-4.66.4-py3-none-any.whl size=78283 sha256=790c82279711a6c4dbc76a2976f3d394e415915b5d4088c378bb9c1c7c5dacc7
#8 8.588   Stored in directory: /tmp/pip-ephem-wheel-cache-_pvmmygp/wheels/70/c8/0a/f308e2a55222b2dcb628088af46602bf45c7c9743347a7f40b
#8 8.593 Successfully built tqdm
#8 8.634 Installing collected packages: tqdm
#8 8.744 Successfully installed tqdm-4.66.4
#8 8.746 WARNING: Running pip as the 'root' user can result in broken permissions and conflicting behaviour with the system package manager. It is recommended to use a virtual environment instead: https://pip.pypa.io/warnings/venv
#8 8.751 
#8 8.751 [notice] A new release of pip is available: 23.0.1 -> 24.0
#8 8.751 [notice] To update, run: pip install --upgrade pip
#8 DONE 8.9s

#9 exporting to image
#9 exporting layers
#9 exporting layers 0.5s done
#9 writing image sha256:753b16567cbd2ae021b874bed67aeda3986a0c7bee201ed63ac5bdb288aff0ec done
#9 naming to docker.io/library/temp_image 0.0s done
#9 DONE 0.5s
Docker build completed successfully on virtual machine.
removing docker image...
clearing temp directory
machine already started
TEMP DIR: /tmp/tmp.jpw2VIDttz


Warning: Permanently added '[localhost]:3022' (ED25519) to the list of known hosts.
#0 building with "default" instance using docker driver

#1 [internal] load build definition from Dockerfile
#1 transferring dockerfile:
#1 transferring dockerfile: 211B done
#1 DONE 0.2s
Dockerfile:4
--------------------
   2 |     
   3 |     # Clone the repository
   4 | >>> git clone https://github.com/tqdm/tqdm.git /tqdm
   5 |     WORKDIR /tqdm
   6 |     
--------------------
ERROR: failed to solve: dockerfile parse error on line 4: unknown instruction: git
removing docker image...
clearing temp directory
machine already started
TEMP DIR: /tmp/tmp.M4fTqaOrnO


Warning: Permanently added '[localhost]:3022' (ED25519) to the list of known hosts.
#0 building with "default" instance using docker driver

#1 [internal] load build definition from Dockerfile
#1 transferring dockerfile: 377B done
#1 DONE 0.1s

#2 [internal] load metadata for docker.io/library/python:3.8
#2 DONE 0.8s

#3 [internal] load .dockerignore
#3 transferring context: 2B done
#3 DONE 0.1s

#4 [1/5] FROM docker.io/library/python:3.8@sha256:01a4da15f16395a2d17dd9b673ccedcd6a6dbb4e130c8056d0d804dedac11c81
#4 DONE 0.0s

#5 [2/5] WORKDIR /app
#5 CACHED

#6 [3/5] RUN git clone https://github.com/user/repo.git
#6 0.392 Cloning into 'repo'...
#6 1.063 fatal: could not read Username for 'https://github.com': No such device or address
#6 ERROR: process "/bin/sh -c git clone https://github.com/user/repo.git" did not complete successfully: exit code: 128
------
 > [3/5] RUN git clone https://github.com/user/repo.git:
0.392 Cloning into 'repo'...
1.063 fatal: could not read Username for 'https://github.com': No such device or address
------
Dockerfile:8
--------------------
   6 |     
   7 |     # Clone the repository from the source
   8 | >>> RUN git clone https://github.com/user/repo.git
   9 |     
  10 |     # Set the working directory to the cloned repository
--------------------
ERROR: failed to solve: process "/bin/sh -c git clone https://github.com/user/repo.git" did not complete successfully: exit code: 128
removing docker image...
clearing temp directory
machine already started
TEMP DIR: /tmp/tmp.2i8NKQI7ES


Warning: Permanently added '[localhost]:3022' (ED25519) to the list of known hosts.
#0 building with "default" instance using docker driver

#1 [internal] load build definition from Dockerfile
#1 transferring dockerfile: 282B done
#1 DONE 0.1s

#2 [internal] load metadata for docker.io/library/python:3.9
#2 DONE 0.8s

#3 [internal] load .dockerignore
#3 transferring context: 2B done
#3 DONE 0.1s

#4 [1/3] FROM docker.io/library/python:3.9@sha256:1446afd121c574b13077f4137443114cd8085f1dade5ee63c08305b5870f2b8a
#4 DONE 0.0s

#5 [2/3] WORKDIR /app
#5 CACHED

#6 [3/3] RUN git clone https://github.com/user/repo.git
#6 0.289 Cloning into 'repo'...
#6 0.654 fatal: could not read Username for 'https://github.com': No such device or address
#6 ERROR: process "/bin/sh -c git clone https://github.com/user/repo.git" did not complete successfully: exit code: 128
------
 > [3/3] RUN git clone https://github.com/user/repo.git:
0.289 Cloning into 'repo'...
0.654 fatal: could not read Username for 'https://github.com': No such device or address
------
Dockerfile:8
--------------------
   6 |     
   7 |     # Clone the repository
   8 | >>> RUN git clone https://github.com/user/repo.git
   9 |     
  10 |     # Run the test suite
--------------------
ERROR: failed to solve: process "/bin/sh -c git clone https://github.com/user/repo.git" did not complete successfully: exit code: 128
removing docker image...
clearing temp directory
machine already started
TEMP DIR: /tmp/tmp.j7JnfYbiME


Warning: Permanently added '[localhost]:3022' (ED25519) to the list of known hosts.
#0 building with "default" instance using docker driver

#1 [internal] load build definition from Dockerfile
#1 transferring dockerfile: 520B done
#1 DONE 0.1s

#2 [internal] load metadata for docker.io/library/python:3.8
#2 DONE 0.9s

#3 [internal] load .dockerignore
#3 transferring context: 2B done
#3 DONE 0.1s

#4 [1/5] FROM docker.io/library/python:3.8@sha256:01a4da15f16395a2d17dd9b673ccedcd6a6dbb4e130c8056d0d804dedac11c81
#4 DONE 0.0s

#5 [2/5] WORKDIR /app
#5 CACHED

#6 [3/5] RUN git clone https://github.com/repository_owner/repository_name.git
#6 0.271 Cloning into 'repository_name'...
#6 1.049 fatal: could not read Username for 'https://github.com': No such device or address
#6 ERROR: process "/bin/sh -c git clone https://github.com/repository_owner/repository_name.git" did not complete successfully: exit code: 128
------
 > [3/5] RUN git clone https://github.com/repository_owner/repository_name.git:
0.271 Cloning into 'repository_name'...
1.049 fatal: could not read Username for 'https://github.com': No such device or address
------
Dockerfile:8
--------------------
   6 |     
   7 |     # Clone the repository from the GitHub URL
   8 | >>> RUN git clone https://github.com/repository_owner/repository_name.git
   9 |     
  10 |     # Set the working directory to the cloned repository
--------------------
ERROR: failed to solve: process "/bin/sh -c git clone https://github.com/repository_owner/repository_name.git" did not complete successfully: exit code: 128
removing docker image...
clearing temp directory
machine already started
TEMP DIR: /tmp/tmp.YxwXSLF1pM


Warning: Permanently added '[localhost]:3022' (ED25519) to the list of known hosts.
#0 building with "default" instance using docker driver

#1 [internal] load build definition from Dockerfile
#1 transferring dockerfile: 331B done
#1 DONE 0.1s

#2 [internal] load metadata for docker.io/library/python:3.8
#2 DONE 1.0s

#3 [internal] load .dockerignore
#3 transferring context: 2B done
#3 DONE 0.1s

#4 [1/4] FROM docker.io/library/python:3.8@sha256:01a4da15f16395a2d17dd9b673ccedcd6a6dbb4e130c8056d0d804dedac11c81
#4 DONE 0.0s

#5 [2/4] WORKDIR /app
#5 CACHED

#6 [3/4] RUN git clone https://github.com/REPLACE_WITH_REPO_URL.git .
#6 0.271 Cloning into '.'...
#6 0.544 remote: Not Found
#6 0.547 fatal: repository 'https://github.com/REPLACE_WITH_REPO_URL.git/' not found
#6 ERROR: process "/bin/sh -c git clone https://github.com/REPLACE_WITH_REPO_URL.git ." did not complete successfully: exit code: 128
------
 > [3/4] RUN git clone https://github.com/REPLACE_WITH_REPO_URL.git .:
0.271 Cloning into '.'...
0.544 remote: Not Found
0.547 fatal: repository 'https://github.com/REPLACE_WITH_REPO_URL.git/' not found
------
Dockerfile:8
--------------------
   6 |     
   7 |     # Clone the repository from GitHub
   8 | >>> RUN git clone https://github.com/REPLACE_WITH_REPO_URL.git .
   9 |     
  10 |     # Run the test suite
--------------------
ERROR: failed to solve: process "/bin/sh -c git clone https://github.com/REPLACE_WITH_REPO_URL.git ." did not complete successfully: exit code: 128
removing docker image...
clearing temp directory
machine already started
TEMP DIR: /tmp/tmp.Zu5y0KcmNV


Warning: Permanently added '[localhost]:3022' (ED25519) to the list of known hosts.
#0 building with "default" instance using docker driver

#1 [internal] load build definition from Dockerfile
#1 transferring dockerfile: 297B done
#1 DONE 0.1s

#2 [internal] load metadata for docker.io/library/python:3.8
#2 DONE 1.1s

#3 [internal] load .dockerignore
#3 transferring context: 2B done
#3 DONE 0.1s

#4 [1/5] FROM docker.io/library/python:3.8@sha256:01a4da15f16395a2d17dd9b673ccedcd6a6dbb4e130c8056d0d804dedac11c81
#4 CACHED

#5 [2/5] RUN apt-get update && apt-get install -y git
#5 0.459 Get:1 http://deb.debian.org/debian bookworm InRelease [151 kB]
#5 0.509 Get:2 http://deb.debian.org/debian bookworm-updates InRelease [55.4 kB]
#5 0.531 Get:3 http://deb.debian.org/debian-security bookworm-security InRelease [48.0 kB]
#5 0.584 Get:4 http://deb.debian.org/debian bookworm/main amd64 Packages [8786 kB]
#5 9.839 Get:5 http://deb.debian.org/debian bookworm-updates/main amd64 Packages [13.8 kB]
#5 9.871 Get:6 http://deb.debian.org/debian-security bookworm-security/main amd64 Packages [156 kB]
#5 10.37 Fetched 9210 kB in 10s (915 kB/s)
#5 10.37 Reading package lists...
#5 10.76 Reading package lists...
#5 11.14 Building dependency tree...
#5 11.23 Reading state information...
#5 11.34 git is already the newest version (1:2.39.2-1.1).
#5 11.34 0 upgraded, 0 newly installed, 0 to remove and 0 not upgraded.
#5 DONE 11.4s

#6 [3/5] WORKDIR /app
#6 DONE 0.1s

#7 [4/5] RUN git clone https://github.com/tqdm/tqdm.git .
#7 0.319 Cloning into '.'...
#7 DONE 8.9s

#8 [5/5] RUN pip install .
#8 1.330 Processing /app
#8 1.335   Installing build dependencies: started
#8 4.606   Installing build dependencies: finished with status 'done'
#8 4.608   Getting requirements to build wheel: started
#8 4.917   Getting requirements to build wheel: finished with status 'done'
#8 4.920   Preparing metadata (pyproject.toml): started
#8 5.187   Preparing metadata (pyproject.toml): finished with status 'done'
#8 5.199 Building wheels for collected packages: tqdm
#8 5.201   Building wheel for tqdm (pyproject.toml): started
#8 5.507   Building wheel for tqdm (pyproject.toml): finished with status 'done'
#8 5.509   Created wheel for tqdm: filename=tqdm-4.66.4-py3-none-any.whl size=78283 sha256=afbcd026556f5b520f72607d7a2427d04cae5289fa6d0ed8ce7cb60c27a70071
#8 5.509   Stored in directory: /tmp/pip-ephem-wheel-cache-s9g0604n/wheels/40/5d/89/f38b7a58cbc6f6bdff423c409ca06a097d4abae527d8c17f06
#8 5.514 Successfully built tqdm
#8 5.541 Installing collected packages: tqdm
#8 5.610 Successfully installed tqdm-4.66.4
#8 5.611 WARNING: Running pip as the 'root' user can result in broken permissions and conflicting behaviour with the system package manager. It is recommended to use a virtual environment instead: https://pip.pypa.io/warnings/venv
#8 5.617 
#8 5.617 [notice] A new release of pip is available: 23.0.1 -> 24.0
#8 5.617 [notice] To update, run: pip install --upgrade pip
#8 DONE 5.8s

#9 exporting to image
#9 exporting layers
#9 exporting layers 0.4s done
#9 writing image sha256:80a6cd299e87facc1f3814e2dd9ad2f931f044188525c34a76f05c73e62725c6 done
#9 naming to docker.io/library/temp_image 0.0s done
#9 DONE 0.4s
Docker build completed successfully on virtual machine.
removing docker image...
clearing temp directory
machine already started
TEMP DIR: /tmp/tmp.mEMkD8kNNP


Warning: Permanently added '[localhost]:3022' (ED25519) to the list of known hosts.
#0 building with "default" instance using docker driver

#1 [internal] load build definition from Dockerfile
#1 transferring dockerfile: 401B done
#1 DONE 0.1s

#2 [internal] load metadata for docker.io/library/python:3
#2 DONE 1.7s

#3 [internal] load .dockerignore
#3 transferring context: 2B done
#3 DONE 0.1s

#4 [1/5] FROM docker.io/library/python:3@sha256:3966b81808d864099f802080d897cef36c01550472ab3955fdd716d1c665acd6
#4 DONE 0.0s

#5 [2/5] WORKDIR /app
#5 CACHED

#6 [3/5] RUN git clone https://github.com/tqdm/tqdm.git
#6 0.256 Cloning into 'tqdm'...
#6 DONE 8.3s

#7 [4/5] WORKDIR /app/tqdm
#7 DONE 0.1s

#8 [5/5] RUN pip install .
#8 1.536 Processing /app/tqdm
#8 1.540   Installing build dependencies: started
#8 5.866   Installing build dependencies: finished with status 'done'
#8 5.867   Getting requirements to build wheel: started
#8 6.165   Getting requirements to build wheel: finished with status 'done'
#8 6.168   Preparing metadata (pyproject.toml): started
#8 6.405   Preparing metadata (pyproject.toml): finished with status 'done'
#8 6.417 Building wheels for collected packages: tqdm
#8 6.418   Building wheel for tqdm (pyproject.toml): started
#8 6.690   Building wheel for tqdm (pyproject.toml): finished with status 'done'
#8 6.691   Created wheel for tqdm: filename=tqdm-4.66.4-py3-none-any.whl size=78283 sha256=beabf9915af59f1126c0fa3788b7f4fdbc2d88d21904fec73ee649b6a310f06d
#8 6.692   Stored in directory: /tmp/pip-ephem-wheel-cache-3gas7qqd/wheels/dc/e3/b3/d5368ae89ba288f3ce8dc123e12ece41351d298eae18b0230e
#8 6.697 Successfully built tqdm
#8 6.750 Installing collected packages: tqdm
#8 6.820 Successfully installed tqdm-4.66.4
#8 6.822 WARNING: Running pip as the 'root' user can result in broken permissions and conflicting behaviour with the system package manager. It is recommended to use a virtual environment instead: https://pip.pypa.io/warnings/venv
#8 DONE 7.0s

#9 exporting to image
#9 exporting layers
#9 exporting layers 0.3s done
#9 writing image sha256:7a5657274734a0e7e777d34d9dfe8a4792c819d788d8432488bddd7543a37f74
#9 writing image sha256:7a5657274734a0e7e777d34d9dfe8a4792c819d788d8432488bddd7543a37f74 0.0s done
#9 naming to docker.io/library/temp_image 0.0s done
#9 DONE 0.3s
Docker build completed successfully on virtual machine.
removing docker image...
clearing temp directory
machine already started
TEMP DIR: /tmp/tmp.fgW7KVfg1X


Warning: Permanently added '[localhost]:3022' (ED25519) to the list of known hosts.
#0 building with "default" instance using docker driver

#1 [internal] load build definition from Dockerfile
#1 transferring dockerfile: 240B done
#1 DONE 0.1s

#2 [internal] load metadata for docker.io/library/python:3.8
#2 DONE 1.2s

#3 [internal] load .dockerignore
#3 transferring context: 2B done
#3 DONE 0.1s

#4 [1/3] FROM docker.io/library/python:3.8@sha256:01a4da15f16395a2d17dd9b673ccedcd6a6dbb4e130c8056d0d804dedac11c81
#4 DONE 0.0s

#5 [2/3] WORKDIR /app
#5 CACHED

#6 [3/3] RUN git clone <repository_url> .
#6 0.322 /bin/sh: 1: cannot open repository_url: No such file
#6 ERROR: process "/bin/sh -c git clone <repository_url> ." did not complete successfully: exit code: 2
------
 > [3/3] RUN git clone <repository_url> .:
cannot open repository_url: No such file
------
Dockerfile:8
--------------------
   6 |     
   7 |     # Clone the repository
   8 | >>> RUN git clone <repository_url> .
   9 |     
  10 |     # Run the test suite
--------------------
ERROR: failed to solve: process "/bin/sh -c git clone <repository_url> ." did not complete successfully: exit code: 2
removing docker image...
clearing temp directory
machine already started
TEMP DIR: /tmp/tmp.IiLt1fYFLm


Warning: Permanently added '[localhost]:3022' (ED25519) to the list of known hosts.
#0 building with "default" instance using docker driver

#1 [internal] load build definition from Dockerfile
#1 transferring dockerfile: 419B done
#1 DONE 0.1s

#2 [internal] load metadata for docker.io/library/python:3
#2 DONE 0.7s

#3 [internal] load .dockerignore
#3 transferring context: 2B done
#3 DONE 0.1s

#4 [1/6] FROM docker.io/library/python:3@sha256:3966b81808d864099f802080d897cef36c01550472ab3955fdd716d1c665acd6
#4 DONE 0.0s

#5 [2/6] WORKDIR /app
#5 CACHED

#6 [3/6] RUN git clone https://github.com/tqdm/tqdm.git
#6 0.275 Cloning into 'tqdm'...
#6 DONE 3.8s

#7 [4/6] WORKDIR /app/tqdm
#7 DONE 0.2s

#8 [5/6] RUN pip install .
#8 1.693 Processing /app/tqdm
#8 1.697   Installing build dependencies: started
#8 4.136   Installing build dependencies: finished with status 'done'
#8 4.137   Getting requirements to build wheel: started
#8 4.424   Getting requirements to build wheel: finished with status 'done'
#8 4.428   Preparing metadata (pyproject.toml): started
#8 4.657   Preparing metadata (pyproject.toml): finished with status 'done'
#8 4.668 Building wheels for collected packages: tqdm
#8 4.669   Building wheel for tqdm (pyproject.toml): started
#8 4.947   Building wheel for tqdm (pyproject.toml): finished with status 'done'
#8 4.948   Created wheel for tqdm: filename=tqdm-4.66.4-py3-none-any.whl size=78283 sha256=aef0f047a9e5c07208d0265228a30e85d9f0334f4f2101a32208345c723a1f30
#8 4.948   Stored in directory: /tmp/pip-ephem-wheel-cache-789yidkz/wheels/dc/e3/b3/d5368ae89ba288f3ce8dc123e12ece41351d298eae18b0230e
#8 4.954 Successfully built tqdm
#8 5.007 Installing collected packages: tqdm
#8 5.066 Successfully installed tqdm-4.66.4
#8 5.067 WARNING: Running pip as the 'root' user can result in broken permissions and conflicting behaviour with the system package manager. It is recommended to use a virtual environment instead: https://pip.pypa.io/warnings/venv
#8 DONE 5.2s

#9 [6/6] RUN python -m unittest discover -s tests
#9 0.448 EEEEEEEEEEEEEEE
#9 0.451 ======================================================================
#9 0.451 ERROR: tests_asyncio (unittest.loader._FailedTest.tests_asyncio)
#9 0.451 ----------------------------------------------------------------------
#9 0.452 ImportError: Failed to import test module: tests_asyncio
#9 0.452 Traceback (most recent call last):
#9 0.452   File "/usr/local/lib/python3.12/unittest/loader.py", line 394, in _find_test_path
#9 0.452     module = self._get_module_from_name(name)
#9 0.452              ^^^^^^^^^^^^^^^^^^^^^^^^^^^^^^^^
#9 0.452   File "/usr/local/lib/python3.12/unittest/loader.py", line 337, in _get_module_from_name
#9 0.452     __import__(name)
#9 0.452   File "/app/tqdm/tests/tests_asyncio.py", line 9, in <module>
#9 0.452     from .tests_tqdm import StringIO, closing, mark
#9 0.452 ImportError: attempted relative import with no known parent package
#9 0.452 
#9 0.452 
#9 0.452 ======================================================================
#9 0.452 ERROR: tests_concurrent (unittest.loader._FailedTest.tests_concurrent)
#9 0.452 ----------------------------------------------------------------------
#9 0.452 ImportError: Failed to import test module: tests_concurrent
#9 0.452 Traceback (most recent call last):
#9 0.452   File "/usr/local/lib/python3.12/unittest/loader.py", line 394, in _find_test_path
#9 0.452     module = self._get_module_from_name(name)
#9 0.452              ^^^^^^^^^^^^^^^^^^^^^^^^^^^^^^^^
#9 0.452   File "/usr/local/lib/python3.12/unittest/loader.py", line 337, in _get_module_from_name
#9 0.452     __import__(name)
#9 0.452   File "/app/tqdm/tests/tests_concurrent.py", line 4, in <module>
#9 0.452     from pytest import warns
#9 0.452 ModuleNotFoundError: No module named 'pytest'
#9 0.452 
#9 0.452 
#9 0.452 ======================================================================
#9 0.452 ERROR: tests_contrib (unittest.loader._FailedTest.tests_contrib)
#9 0.453 ----------------------------------------------------------------------
#9 0.453 ImportError: Failed to import test module: tests_contrib
#9 0.453 Traceback (most recent call last):
#9 0.453   File "/usr/local/lib/python3.12/unittest/loader.py", line 394, in _find_test_path
#9 0.453     module = self._get_module_from_name(name)
#9 0.453              ^^^^^^^^^^^^^^^^^^^^^^^^^^^^^^^^
#9 0.453   File "/usr/local/lib/python3.12/unittest/loader.py", line 337, in _get_module_from_name
#9 0.453     __import__(name)
#9 0.453   File "/app/tqdm/tests/tests_contrib.py", line 4, in <module>
#9 0.453     import pytest
#9 0.453 ModuleNotFoundError: No module named 'pytest'
#9 0.453 
#9 0.453 
#9 0.453 ======================================================================
#9 0.453 ERROR: tests_contrib_logging (unittest.loader._FailedTest.tests_contrib_logging)
#9 0.453 ----------------------------------------------------------------------
#9 0.453 ImportError: Failed to import test module: tests_contrib_logging
#9 0.453 Traceback (most recent call last):
#9 0.453   File "/usr/local/lib/python3.12/unittest/loader.py", line 394, in _find_test_path
#9 0.453     module = self._get_module_from_name(name)
#9 0.453              ^^^^^^^^^^^^^^^^^^^^^^^^^^^^^^^^
#9 0.453   File "/usr/local/lib/python3.12/unittest/loader.py", line 337, in _get_module_from_name
#9 0.453     __import__(name)
#9 0.453   File "/app/tqdm/tests/tests_contrib_logging.py", line 8, in <module>
#9 0.453     import pytest
#9 0.453 ModuleNotFoundError: No module named 'pytest'
#9 0.453 
#9 0.453 
#9 0.453 ======================================================================
#9 0.453 ERROR: tests_dask (unittest.loader._FailedTest.tests_dask)
#9 0.454 ----------------------------------------------------------------------
#9 0.454 ImportError: Failed to import test module: tests_dask
#9 0.454 Traceback (most recent call last):
#9 0.454   File "/usr/local/lib/python3.12/unittest/loader.py", line 394, in _find_test_path
#9 0.454     module = self._get_module_from_name(name)
#9 0.454              ^^^^^^^^^^^^^^^^^^^^^^^^^^^^^^^^
#9 0.454   File "/usr/local/lib/python3.12/unittest/loader.py", line 337, in _get_module_from_name
#9 0.454     __import__(name)
#9 0.454   File "/app/tqdm/tests/tests_dask.py", line 3, in <module>
#9 0.454     from .tests_tqdm import importorskip, mark
#9 0.454 ImportError: attempted relative import with no known parent package
#9 0.454 
#9 0.454 
#9 0.454 ======================================================================
#9 0.454 ERROR: tests_gui (unittest.loader._FailedTest.tests_gui)
#9 0.454 ----------------------------------------------------------------------
#9 0.454 ImportError: Failed to import test module: tests_gui
#9 0.454 Traceback (most recent call last):
#9 0.454   File "/usr/local/lib/python3.12/unittest/loader.py", line 394, in _find_test_path
#9 0.454     module = self._get_module_from_name(name)
#9 0.454              ^^^^^^^^^^^^^^^^^^^^^^^^^^^^^^^^
#9 0.454   File "/usr/local/lib/python3.12/unittest/loader.py", line 337, in _get_module_from_name
#9 0.454     __import__(name)
#9 0.454   File "/app/tqdm/tests/tests_gui.py", line 2, in <module>
#9 0.454     from .tests_tqdm import importorskip
#9 0.454 ImportError: attempted relative import with no known parent package
#9 0.454 
#9 0.454 
#9 0.454 ======================================================================
#9 0.455 ERROR: tests_itertools (unittest.loader._FailedTest.tests_itertools)
#9 0.455 ----------------------------------------------------------------------
#9 0.455 ImportError: Failed to import test module: tests_itertools
#9 0.455 Traceback (most recent call last):
#9 0.455   File "/usr/local/lib/python3.12/unittest/loader.py", line 394, in _find_test_path
#9 0.455     module = self._get_module_from_name(name)
#9 0.455              ^^^^^^^^^^^^^^^^^^^^^^^^^^^^^^^^
#9 0.455   File "/usr/local/lib/python3.12/unittest/loader.py", line 337, in _get_module_from_name
#9 0.455     __import__(name)
#9 0.455   File "/app/tqdm/tests/tests_itertools.py", line 8, in <module>
#9 0.455     from .tests_tqdm import StringIO, closing
#9 0.455 ImportError: attempted relative import with no known parent package
#9 0.455 
#9 0.455 
#9 0.455 ======================================================================
#9 0.455 ERROR: tests_keras (unittest.loader._FailedTest.tests_keras)
#9 0.455 ----------------------------------------------------------------------
#9 0.465 ImportError: Failed to import test module: tests_keras
#9 0.465 Traceback (most recent call last):
#9 0.465   File "/usr/local/lib/python3.12/unittest/loader.py", line 394, in _find_test_path
#9 0.465     module = self._get_module_from_name(name)
#9 0.465              ^^^^^^^^^^^^^^^^^^^^^^^^^^^^^^^^
#9 0.465   File "/usr/local/lib/python3.12/unittest/loader.py", line 337, in _get_module_from_name
#9 0.465     __import__(name)
#9 0.465   File "/app/tqdm/tests/tests_keras.py", line 1, in <module>
#9 0.465     from .tests_tqdm import importorskip, mark
#9 0.465 ImportError: attempted relative import with no known parent package
#9 0.465 
#9 0.465 
#9 0.465 ======================================================================
#9 0.465 ERROR: tests_main (unittest.loader._FailedTest.tests_main)
#9 0.465 ----------------------------------------------------------------------
#9 0.465 ImportError: Failed to import test module: tests_main
#9 0.465 Traceback (most recent call last):
#9 0.465   File "/usr/local/lib/python3.12/unittest/loader.py", line 394, in _find_test_path
#9 0.465     module = self._get_module_from_name(name)
#9 0.465              ^^^^^^^^^^^^^^^^^^^^^^^^^^^^^^^^
#9 0.465   File "/usr/local/lib/python3.12/unittest/loader.py", line 337, in _get_module_from_name
#9 0.465     __import__(name)
#9 0.465   File "/app/tqdm/tests/tests_main.py", line 11, in <module>
#9 0.465     from .tests_tqdm import BytesIO, closing, mark, raises
#9 0.465 ImportError: attempted relative import with no known parent package
#9 0.465 
#9 0.465 
#9 0.465 ======================================================================
#9 0.465 ERROR: tests_pandas (unittest.loader._FailedTest.tests_pandas)
#9 0.465 ----------------------------------------------------------------------
#9 0.465 ImportError: Failed to import test module: tests_pandas
#9 0.465 Traceback (most recent call last):
#9 0.465   File "/usr/local/lib/python3.12/unittest/loader.py", line 394, in _find_test_path
#9 0.465     module = self._get_module_from_name(name)
#9 0.465              ^^^^^^^^^^^^^^^^^^^^^^^^^^^^^^^^
#9 0.465   File "/usr/local/lib/python3.12/unittest/loader.py", line 337, in _get_module_from_name
#9 0.465     __import__(name)
#9 0.465   File "/app/tqdm/tests/tests_pandas.py", line 3, in <module>
#9 0.465     from .tests_tqdm import StringIO, closing, importorskip, mark, skip
#9 0.465 ImportError: attempted relative import with no known parent package
#9 0.465 
#9 0.465 
#9 0.465 ======================================================================
#9 0.465 ERROR: tests_perf (unittest.loader._FailedTest.tests_perf)
#9 0.465 ----------------------------------------------------------------------
#9 0.465 ImportError: Failed to import test module: tests_perf
#9 0.465 Traceback (most recent call last):
#9 0.465   File "/usr/local/lib/python3.12/unittest/loader.py", line 394, in _find_test_path
#9 0.465     module = self._get_module_from_name(name)
#9 0.465              ^^^^^^^^^^^^^^^^^^^^^^^^^^^^^^^^
#9 0.465   File "/usr/local/lib/python3.12/unittest/loader.py", line 337, in _get_module_from_name
#9 0.465     __import__(name)
#9 0.465   File "/app/tqdm/tests/tests_perf.py", line 15, in <module>
#9 0.465     from .tests_tqdm import importorskip, mark, patch_lock, skip
#9 0.465 ImportError: attempted relative import with no known parent package
#9 0.465 
#9 0.465 
#9 0.465 ======================================================================
#9 0.465 ERROR: tests_rich (unittest.loader._FailedTest.tests_rich)
#9 0.465 ----------------------------------------------------------------------
#9 0.465 ImportError: Failed to import test module: tests_rich
#9 0.465 Traceback (most recent call last):
#9 0.465   File "/usr/local/lib/python3.12/unittest/loader.py", line 394, in _find_test_path
#9 0.465     module = self._get_module_from_name(name)
#9 0.465              ^^^^^^^^^^^^^^^^^^^^^^^^^^^^^^^^
#9 0.465   File "/usr/local/lib/python3.12/unittest/loader.py", line 337, in _get_module_from_name
#9 0.465     __import__(name)
#9 0.465   File "/app/tqdm/tests/tests_rich.py", line 2, in <module>
#9 0.465     from .tests_tqdm import importorskip
#9 0.465 ImportError: attempted relative import with no known parent package
#9 0.465 
#9 0.465 
#9 0.465 ======================================================================
#9 0.465 ERROR: tests_synchronisation (unittest.loader._FailedTest.tests_synchronisation)
#9 0.465 ----------------------------------------------------------------------
#9 0.465 ImportError: Failed to import test module: tests_synchronisation
#9 0.465 Traceback (most recent call last):
#9 0.465   File "/usr/local/lib/python3.12/unittest/loader.py", line 394, in _find_test_path
#9 0.465     module = self._get_module_from_name(name)
#9 0.465              ^^^^^^^^^^^^^^^^^^^^^^^^^^^^^^^^
#9 0.465   File "/usr/local/lib/python3.12/unittest/loader.py", line 337, in _get_module_from_name
#9 0.465     __import__(name)
#9 0.465   File "/app/tqdm/tests/tests_synchronisation.py", line 7, in <module>
#9 0.465     from .tests_tqdm import StringIO, closing, importorskip, patch_lock, skip
#9 0.465 ImportError: attempted relative import with no known parent package
#9 0.465 
#9 0.465 
#9 0.465 ======================================================================
#9 0.465 ERROR: tests_tk (unittest.loader._FailedTest.tests_tk)
#9 0.465 ----------------------------------------------------------------------
#9 0.465 ImportError: Failed to import test module: tests_tk
#9 0.465 Traceback (most recent call last):
#9 0.465   File "/usr/local/lib/python3.12/unittest/loader.py", line 394, in _find_test_path
#9 0.465     module = self._get_module_from_name(name)
#9 0.465              ^^^^^^^^^^^^^^^^^^^^^^^^^^^^^^^^
#9 0.465   File "/usr/local/lib/python3.12/unittest/loader.py", line 337, in _get_module_from_name
#9 0.465     __import__(name)
#9 0.465   File "/app/tqdm/tests/tests_tk.py", line 2, in <module>
#9 0.465     from .tests_tqdm import importorskip
#9 0.465 ImportError: attempted relative import with no known parent package
#9 0.465 
#9 0.465 
#9 0.465 ======================================================================
#9 0.465 ERROR: tests_tqdm (unittest.loader._FailedTest.tests_tqdm)
#9 0.465 ----------------------------------------------------------------------
#9 0.465 ImportError: Failed to import test module: tests_tqdm
#9 0.465 Traceback (most recent call last):
#9 0.465   File "/usr/local/lib/python3.12/unittest/loader.py", line 394, in _find_test_path
#9 0.465     module = self._get_module_from_name(name)
#9 0.465              ^^^^^^^^^^^^^^^^^^^^^^^^^^^^^^^^
#9 0.465   File "/usr/local/lib/python3.12/unittest/loader.py", line 337, in _get_module_from_name
#9 0.465     __import__(name)
#9 0.465   File "/app/tqdm/tests/tests_tqdm.py", line 12, in <module>
#9 0.465     from pytest import importorskip, mark, raises, skip
#9 0.465 ModuleNotFoundError: No module named 'pytest'
#9 0.465 
#9 0.465 
#9 0.465 ----------------------------------------------------------------------
#9 0.465 Ran 15 tests in 0.003s
#9 0.465 
#9 0.465 FAILED (errors=15)
#9 ERROR: process "/bin/sh -c python -m unittest discover -s tests" did not complete successfully: exit code: 1
------
 > [6/6] RUN python -m unittest discover -s tests:
0.465     __import__(name)
0.465   File "/app/tqdm/tests/tests_tqdm.py", line 12, in <module>
0.465     from pytest import importorskip, mark, raises, skip
0.465 ModuleNotFoundError: No module named 'pytest'
0.465 
0.465 
0.465 ----------------------------------------------------------------------
0.465 Ran 15 tests in 0.003s
0.465 
0.465 FAILED (errors=15)
------
Dockerfile:17
--------------------
  15 |     
  16 |     # Run the test suite
  17 | >>> RUN python -m unittest discover -s tests
  18 |     
--------------------
ERROR: failed to solve: process "/bin/sh -c python -m unittest discover -s tests" did not complete successfully: exit code: 1
removing docker image...
clearing temp directory
